Traceback (most recent call last):
  File "D:\sys_bot_gemini\smart_chatbot.py", line 99, in <module>
    chat.send_message(intro_prompt)
  File "C:\Users\Kavivarman\AppData\Local\Programs\Python\Python310\lib\site-packages\google\generativeai\generative_models.py", line 474, in send_message
    response = self.model.generate_content(
  File "C:\Users\Kavivarman\AppData\Local\Programs\Python\Python310\lib\site-packages\google\generativeai\generative_models.py", line 262, in generate_content
    response = self._client.generate_content(
  File "C:\Users\Kavivarman\AppData\Local\Programs\Python\Python310\lib\site-packages\google\ai\generativelanguage_v1beta\services\generative_service\client.py", line 791, in generate_content
    response = rpc(
  File "C:\Users\Kavivarman\AppData\Local\Programs\Python\Python310\lib\site-packages\google\api_core\gapic_v1\method.py", line 131, in __call__
    return wrapped_func(*args, **kwargs)
  File "C:\Users\Kavivarman\AppData\Local\Programs\Python\Python310\lib\site-packages\google\api_core\retry\retry_unary.py", line 293, in retry_wrapped_func
    return retry_target(
  File "C:\Users\Kavivarman\AppData\Local\Programs\Python\Python310\lib\site-packages\google\api_core\retry\retry_unary.py", line 153, in retry_target
    _retry_error_helper(
  File "C:\Users\Kavivarman\AppData\Local\Programs\Python\Python310\lib\site-packages\google\api_core\retry\retry_base.py", line 212, in _retry_error_helper
    raise final_exc from source_exc
  File "C:\Users\Kavivarman\AppData\Local\Programs\Python\Python310\lib\site-packages\google\api_core\retry\retry_unary.py", line 144, in retry_target
    result = target()
  File "C:\Users\Kavivarman\AppData\Local\Programs\Python\Python310\lib\site-packages\google\api_core\timeout.py", line 130, in func_with_timeout
    return func(*args, **kwargs)
  File "C:\Users\Kavivarman\AppData\Local\Programs\Python\Python310\lib\site-packages\google\api_core\grpc_helpers.py", line 78, in error_remapped_callable
    raise exceptions.from_grpc_error(exc) from exc
google.api_core.exceptions.ResourceExhausted: 429 You exceeded your current quota, please check your plan and billing details. For more information on this error, head to: https://ai.google.dev/gemini-api/docs/rate-limits. [violations {
  quota_metric: "generativelanguage.googleapis.com/generate_content_free_tier_requests"
  quota_id: "GenerateRequestsPerDayPerProjectPerModel-FreeTier"
  quota_dimensions {
    key: "model"
    value: "gemini-1.5-flash"
  }
  quota_dimensions {
    key: "location"
    value: "global"
  }
  quota_value: 50
}
, links {
  description: "Learn more about Gemini API quotas"
  url: "https://ai.google.dev/gemini-api/docs/rate-limits"
}
, retry_delay {
  seconds: 8
}
]
